Traceback (most recent call last):
  File "c:\users\æ€¡æ¨º\hellodjango\lib\site-packages\jupyter_cache\executors\utils.py", line 56, in single_nb_execution
    record_timing=False,
  File "c:\users\æ€¡æ¨º\hellodjango\lib\site-packages\nbclient\client.py", line 1082, in execute
    return NotebookClient(nb=nb, resources=resources, km=km, **kwargs).execute()
  File "c:\users\æ€¡æ¨º\hellodjango\lib\site-packages\nbclient\util.py", line 74, in wrapped
    return just_run(coro(*args, **kwargs))
  File "c:\users\æ€¡æ¨º\hellodjango\lib\site-packages\nbclient\util.py", line 53, in just_run
    return loop.run_until_complete(coro)
  File "C:\Users\æ€¡æ¨º\AppData\Local\Programs\Python\Python36-32\lib\asyncio\base_events.py", line 467, in run_until_complete
    return future.result()
  File "c:\users\æ€¡æ¨º\hellodjango\lib\site-packages\nbclient\client.py", line 536, in async_execute
    cell, index, execution_count=self.code_cells_executed + 1
  File "c:\users\æ€¡æ¨º\hellodjango\lib\site-packages\nbclient\client.py", line 827, in async_execute_cell
    self._check_raise_for_error(cell, exec_reply)
  File "c:\users\æ€¡æ¨º\hellodjango\lib\site-packages\nbclient\client.py", line 735, in _check_raise_for_error
    raise CellExecutionError.from_cell_and_msg(cell, exec_reply['content'])
nbclient.exceptions.CellExecutionError: An error occurred while executing the following cell:
------------------
import tensorflow as tf
import numpy as np
import matplotlib.pyplot as plt
from keras.utils import np_utils
------------------

[1;31m---------------------------------------------------------------------------[0m
[1;31mImportError[0m                               Traceback (most recent call last)
[1;32mc:\users\æ€¡æ¨º\hellodjango\lib\site-packages\tensorflow\python\pywrap_tensorflow.py[0m in [0;36mswig_import_helper[1;34m()[0m
[0;32m     17[0m         [1;32mtry[0m[1;33m:[0m[1;33m[0m[0m
[1;32m---> 18[1;33m             [0mfp[0m[1;33m,[0m [0mpathname[0m[1;33m,[0m [0mdescription[0m [1;33m=[0m [0mimp[0m[1;33m.[0m[0mfind_module[0m[1;33m([0m[1;34m'_pywrap_tensorflow'[0m[1;33m,[0m [1;33m[[0m[0mdirname[0m[1;33m([0m[0m__file__[0m[1;33m)[0m[1;33m][0m[1;33m)[0m[1;33m[0m[0m
[0m[0;32m     19[0m         [1;32mexcept[0m [0mImportError[0m[1;33m:[0m[1;33m[0m[0m

[1;32m~\AppData\Local\Programs\Python\Python36-32\lib\imp.py[0m in [0;36mfind_module[1;34m(name, path)[0m
[0;32m    296[0m     [1;32melse[0m[1;33m:[0m[1;33m[0m[0m
[1;32m--> 297[1;33m         [1;32mraise[0m [0mImportError[0m[1;33m([0m[0m_ERR_MSG[0m[1;33m.[0m[0mformat[0m[1;33m([0m[0mname[0m[1;33m)[0m[1;33m,[0m [0mname[0m[1;33m=[0m[0mname[0m[1;33m)[0m[1;33m[0m[0m
[0m[0;32m    298[0m [1;33m[0m[0m

[1;31mImportError[0m: No module named '_pywrap_tensorflow'

During handling of the above exception, another exception occurred:

[1;31mModuleNotFoundError[0m                       Traceback (most recent call last)
[1;32mc:\users\æ€¡æ¨º\hellodjango\lib\site-packages\tensorflow\python\__init__.py[0m in [0;36m<module>[1;34m[0m
[0;32m     65[0m     [1;31m# use `dlopen()` for dynamic loading.[0m[1;33m[0m[1;33m[0m[0m
[1;32m---> 66[1;33m     [1;32mfrom[0m [0mtensorflow[0m[1;33m.[0m[0mpython[0m [1;32mimport[0m [0mpywrap_tensorflow[0m[1;33m[0m[0m
[0m[0;32m     67[0m [1;32mexcept[0m [0mImportError[0m[1;33m:[0m[1;33m[0m[0m

[1;32mc:\users\æ€¡æ¨º\hellodjango\lib\site-packages\tensorflow\python\pywrap_tensorflow.py[0m in [0;36m<module>[1;34m[0m
[0;32m     27[0m             [1;32mreturn[0m [0m_mod[0m[1;33m[0m[0m
[1;32m---> 28[1;33m     [0m_pywrap_tensorflow[0m [1;33m=[0m [0mswig_import_helper[0m[1;33m([0m[1;33m)[0m[1;33m[0m[0m
[0m[0;32m     29[0m     [1;32mdel[0m [0mswig_import_helper[0m[1;33m[0m[0m

[1;32mc:\users\æ€¡æ¨º\hellodjango\lib\site-packages\tensorflow\python\pywrap_tensorflow.py[0m in [0;36mswig_import_helper[1;34m()[0m
[0;32m     19[0m         [1;32mexcept[0m [0mImportError[0m[1;33m:[0m[1;33m[0m[0m
[1;32m---> 20[1;33m             [1;32mimport[0m [0m_pywrap_tensorflow[0m[1;33m[0m[0m
[0m[0;32m     21[0m             [1;32mreturn[0m [0m_pywrap_tensorflow[0m[1;33m[0m[0m

[1;31mModuleNotFoundError[0m: No module named '_pywrap_tensorflow'

During handling of the above exception, another exception occurred:

[1;31mImportError[0m                               Traceback (most recent call last)
[1;32m<ipython-input-1-392282ad3d40>[0m in [0;36m<module>[1;34m[0m
[1;32m----> 1[1;33m [1;32mimport[0m [0mtensorflow[0m [1;32mas[0m [0mtf[0m[1;33m[0m[0m
[0m[0;32m      2[0m [1;32mimport[0m [0mnumpy[0m [1;32mas[0m [0mnp[0m[1;33m[0m[0m
[0;32m      3[0m [1;32mimport[0m [0mmatplotlib[0m[1;33m.[0m[0mpyplot[0m [1;32mas[0m [0mplt[0m[1;33m[0m[0m
[0;32m      4[0m [1;32mfrom[0m [0mkeras[0m[1;33m.[0m[0mutils[0m [1;32mimport[0m [0mnp_utils[0m[1;33m[0m[0m

[1;32mc:\users\æ€¡æ¨º\hellodjango\lib\site-packages\tensorflow\__init__.py[0m in [0;36m<module>[1;34m[0m
[0;32m     22[0m [1;33m[0m[0m
[0;32m     23[0m [1;31m# pylint: disable=wildcard-import[0m[1;33m[0m[1;33m[0m[0m
[1;32m---> 24[1;33m [1;32mfrom[0m [0mtensorflow[0m[1;33m.[0m[0mpython[0m [1;32mimport[0m [1;33m*[0m[1;33m[0m[0m
[0m[0;32m     25[0m [1;31m# pylint: enable=wildcard-import[0m[1;33m[0m[1;33m[0m[0m
[0;32m     26[0m [1;33m[0m[0m

[1;32mc:\users\æ€¡æ¨º\hellodjango\lib\site-packages\tensorflow\python\__init__.py[0m in [0;36m<module>[1;34m[0m
[0;32m     70[0m [1;32mfor[0m [0msome[0m [0mcommon[0m [0mreasons[0m [1;32mand[0m [0msolutions[0m[1;33m.[0m  [0mInclude[0m [0mthe[0m [0mentire[0m [0mstack[0m [0mtrace[0m[1;33m[0m[0m
[0;32m     71[0m above this error message when asking for help.""" % traceback.format_exc()
[1;32m---> 72[1;33m   [1;32mraise[0m [0mImportError[0m[1;33m([0m[0mmsg[0m[1;33m)[0m[1;33m[0m[0m
[0m[0;32m     73[0m [1;33m[0m[0m
[0;32m     74[0m [1;31m# Protocol buffers[0m[1;33m[0m[1;33m[0m[0m

[1;31mImportError[0m: Traceback (most recent call last):
  File "c:\users\æ€¡æ¨º\hellodjango\lib\site-packages\tensorflow\python\pywrap_tensorflow.py", line 18, in swig_import_helper
    fp, pathname, description = imp.find_module('_pywrap_tensorflow', [dirname(__file__)])
  File "C:\Users\æ€¡æ¨º\AppData\Local\Programs\Python\Python36-32\lib\imp.py", line 297, in find_module
    raise ImportError(_ERR_MSG.format(name), name=name)
ImportError: No module named '_pywrap_tensorflow'

During handling of the above exception, another exception occurred:

Traceback (most recent call last):
  File "c:\users\æ€¡æ¨º\hellodjango\lib\site-packages\tensorflow\python\__init__.py", line 66, in <module>
    from tensorflow.python import pywrap_tensorflow
  File "c:\users\æ€¡æ¨º\hellodjango\lib\site-packages\tensorflow\python\pywrap_tensorflow.py", line 28, in <module>
    _pywrap_tensorflow = swig_import_helper()
  File "c:\users\æ€¡æ¨º\hellodjango\lib\site-packages\tensorflow\python\pywrap_tensorflow.py", line 20, in swig_import_helper
    import _pywrap_tensorflow
ModuleNotFoundError: No module named '_pywrap_tensorflow'


Failed to load the native TensorFlow runtime.

See https://github.com/tensorflow/tensorflow/blob/master/tensorflow/g3doc/get_started/os_setup.md#import_error

for some common reasons and solutions.  Include the entire stack trace
above this error message when asking for help.
ImportError: Traceback (most recent call last):
  File "c:\users\æ€¡æ¨º\hellodjango\lib\site-packages\tensorflow\python\pywrap_tensorflow.py", line 18, in swig_import_helper
    fp, pathname, description = imp.find_module('_pywrap_tensorflow', [dirname(__file__)])
  File "C:\Users\æ€¡æ¨º\AppData\Local\Programs\Python\Python36-32\lib\imp.py", line 297, in find_module
    raise ImportError(_ERR_MSG.format(name), name=name)
ImportError: No module named '_pywrap_tensorflow'

During handling of the above exception, another exception occurred:

Traceback (most recent call last):
  File "c:\users\æ€¡æ¨º\hellodjango\lib\site-packages\tensorflow\python\__init__.py", line 66, in <module>
    from tensorflow.python import pywrap_tensorflow
  File "c:\users\æ€¡æ¨º\hellodjango\lib\site-packages\tensorflow\python\pywrap_tensorflow.py", line 28, in <module>
    _pywrap_tensorflow = swig_import_helper()
  File "c:\users\æ€¡æ¨º\hellodjango\lib\site-packages\tensorflow\python\pywrap_tensorflow.py", line 20, in swig_import_helper
    import _pywrap_tensorflow
ModuleNotFoundError: No module named '_pywrap_tensorflow'


Failed to load the native TensorFlow runtime.

See https://github.com/tensorflow/tensorflow/blob/master/tensorflow/g3doc/get_started/os_setup.md#import_error

for some common reasons and solutions.  Include the entire stack trace
above this error message when asking for help.

