Traceback (most recent call last):
  File "c:\users\æ€¡æ¨º\hellodjango\lib\site-packages\jupyter_cache\executors\utils.py", line 56, in single_nb_execution
    record_timing=False,
  File "c:\users\æ€¡æ¨º\hellodjango\lib\site-packages\nbclient\client.py", line 1082, in execute
    return NotebookClient(nb=nb, resources=resources, km=km, **kwargs).execute()
  File "c:\users\æ€¡æ¨º\hellodjango\lib\site-packages\nbclient\util.py", line 74, in wrapped
    return just_run(coro(*args, **kwargs))
  File "c:\users\æ€¡æ¨º\hellodjango\lib\site-packages\nbclient\util.py", line 53, in just_run
    return loop.run_until_complete(coro)
  File "C:\Users\æ€¡æ¨º\AppData\Local\Programs\Python\Python36-32\lib\asyncio\base_events.py", line 467, in run_until_complete
    return future.result()
  File "c:\users\æ€¡æ¨º\hellodjango\lib\site-packages\nbclient\client.py", line 536, in async_execute
    cell, index, execution_count=self.code_cells_executed + 1
  File "c:\users\æ€¡æ¨º\hellodjango\lib\site-packages\nbclient\client.py", line 827, in async_execute_cell
    self._check_raise_for_error(cell, exec_reply)
  File "c:\users\æ€¡æ¨º\hellodjango\lib\site-packages\nbclient\client.py", line 735, in _check_raise_for_error
    raise CellExecutionError.from_cell_and_msg(cell, exec_reply['content'])
nbclient.exceptions.CellExecutionError: An error occurred while executing the following cell:
------------------
import pandas as pd
------------------

[1;31m---------------------------------------------------------------------------[0m
[1;31mModuleNotFoundError[0m                       Traceback (most recent call last)
[1;32m<ipython-input-1-7dd3504c366f>[0m in [0;36m<module>[1;34m[0m
[1;32m----> 1[1;33m [1;32mimport[0m [0mpandas[0m [1;32mas[0m [0mpd[0m[1;33m[0m[0m
[0m
[1;31mModuleNotFoundError[0m: No module named 'pandas'
ModuleNotFoundError: No module named 'pandas'

